#VRML_SIM R2021b utf8
WorldInfo {
  coordinateSystem "NUE"
}
Viewpoint {
  orientation -0.5444508525106535 -0.8139643862966373 -0.20257158497963504 0.7905098728077852
  position -0.8840076108720906 0.7985659561919579 1.2693183268964072
}
Robot {
  translation -0.0234912 0.08 -0.03764
  children [
    DEF wheel_r1 HingeJoint {
      jointParameters HingeJointParameters {
        axis 0 0 1
        anchor 0.1 -0.0599997 0.1
      }
      device [
        RotationalMotor {
          name "wheel_r1"
        }
      ]
      endPoint Solid {
        translation 0.1 -0.0599997 0.1
        rotation 1 0 0 1.5708
        children [
          DEF kerek1 Shape {
            appearance PBRAppearance {
              baseColor 0.2 0.6 1
            }
            geometry Cylinder {
              height 0.02
              radius 0.02
            }
          }
        ]
        boundingObject USE kerek1
        physics Physics {
        }
      }
    }
    DEF wheel_l1 HingeJoint {
      jointParameters HingeJointParameters {
        axis 0 0 1
        anchor 0.1 -0.0599997 -0.1
      }
      device [
        RotationalMotor {
          name "wheel_l1"
        }
      ]
      endPoint Solid {
        translation 0.1 -0.0599997 -0.1
        rotation 1 0 0 1.5708
        children [
          DEF kerek2 Shape {
            appearance PBRAppearance {
              baseColor 0.2 0.6 1
            }
            geometry Cylinder {
              height 0.02
              radius 0.02
            }
          }
        ]
        name "solid(3)"
        boundingObject USE kerek2
        physics Physics {
        }
      }
    }
    DEF wheel_r2 HingeJoint {
      jointParameters HingeJointParameters {
        axis 0 0 1
        anchor 0.01 -0.0599997 0.1
      }
      device [
        RotationalMotor {
          name "wheel_r2"
        }
      ]
      endPoint Solid {
        translation 0.01 -0.0599997 0.1
        rotation 1 0 0 1.5708
        children [
          DEF kerek3 Shape {
            appearance PBRAppearance {
              baseColor 0.2 0.6 1
            }
            geometry Cylinder {
              height 0.02
              radius 0.02
            }
          }
        ]
        name "solid(1)"
        boundingObject USE kerek3
        physics Physics {
        }
      }
    }
    DEF wheel_l2 HingeJoint {
      jointParameters HingeJointParameters {
        axis 0 0 1
        anchor 0.01 -0.0599997 -0.1
      }
      device [
        RotationalMotor {
          name "wheel_l2"
        }
      ]
      endPoint Solid {
        translation 0.01 -0.0599997 -0.1
        rotation 1 0 0 1.5708
        children [
          DEF kerek4 Shape {
            appearance PBRAppearance {
              baseColor 0.2 0.6 1
            }
            geometry Cylinder {
              height 0.02
              radius 0.02
            }
          }
        ]
        name "solid(4)"
        boundingObject USE kerek4
        physics Physics {
        }
      }
    }
    DEF wheel_r3 HingeJoint {
      jointParameters HingeJointParameters {
        axis 0 0 1
        anchor -0.09 -0.0599997 0.1
      }
      device [
        RotationalMotor {
          name "wheel_r3"
        }
      ]
      endPoint Solid {
        translation -0.09 -0.0599997 0.1
        rotation 1 0 0 1.5708
        children [
          DEF kerek5 Shape {
            appearance PBRAppearance {
              baseColor 0.2 0.6 1
            }
            geometry Cylinder {
              height 0.02
              radius 0.02
            }
          }
        ]
        name "solid(2)"
        boundingObject USE kerek5
        physics Physics {
        }
      }
    }
    DEF wheel_l3 HingeJoint {
      jointParameters HingeJointParameters {
        axis 0 0 1
        anchor -0.09 -0.0599996 -0.1
      }
      device [
        RotationalMotor {
          name "wheel_l3"
        }
      ]
      endPoint Solid {
        translation -0.09 -0.0599996 -0.1
        rotation 1 0 0 1.5708
        children [
          DEF kerek6 Shape {
            appearance PBRAppearance {
              baseColor 0.2 0.6 1
            }
            geometry Cylinder {
              height 0.02
              radius 0.02
            }
          }
        ]
        name "solid(5)"
        boundingObject USE kerek6
        physics Physics {
        }
      }
    }
    DEF body Transform {
      children [
        Shape {
          appearance PBRAppearance {
          }
          geometry Box {
            size 0.27 0.126 0.18
          }
        }
      ]
    }
  ]
  boundingObject USE body
  physics Physics {
    mass 0.7
  }
  controller "robcontroller"
}
TexturedBackground {
}
TexturedBackgroundLight {
}
RectangleArena {
  floorSize 4 4
  wallHeight 0.3
}
